<?xml version="1.0"?>
<robot xmlns:xacro="http://www.ros.org/wiki/xacro" name="zeus">

  <xacro:include filename="$(find steve_description)/urdf/accessories/camera.urdf.xacro"/>
  <xacro:include filename="$(find steve_description)/urdf/accessories/realsense_d435.urdf.xacro" />

  <xacro:property name="deg90" value="1.57075" />
  <xacro:property name="deg45" value="0.7854" />
  <xacro:property name="frame_width" value="0.6" />
  <xacro:property name="frame_height" value="0.3" />
  <xacro:property name="frame_length" value="0.82" />
  <xacro:property name="frame_mass" value="50" />
  <xacro:property name="rocker_mass" value="10" />
  <xacro:property name="bogie_mass" value="10" />
  <xacro:property name="wheel_radius" value="0.1" />
  <xacro:property name="wheel_width" value="0.1" />
  <xacro:property name="wheel_mass" value="1" />
  <xacro:property name="wheel_mu1" value="0.2" />
  <xacro:property name="wheel_mu2" value="3.0" />
  <xacro:property name="wheel_kp" value="10000000.0" />
  <xacro:property name="wheel_kd" value="1" />

  <!-- High level dummy link for ODE -->
  <link name="base_link">
  </link>

  <!-- Frame -->
  <link name="frame_link">
    <visual>
      <geometry>
        <mesh filename="file://$(find zeus_description)/STL/Z1.stl"/>
      </geometry>
      <origin rpy="${deg90} 0 0" xyz="0 0 0"/>
    </visual>
    <collision>
      <geometry>
        <box size="${frame_length} ${frame_width} ${frame_height}"/>
      </geometry>
      <origin rpy="0 0 0" xyz="-0.27 -0.02 -0.45"/>
    </collision>
    <inertial>
      <mass value="${frame_mass}"/>
      <inertia ixx="4" ixy="0.0" ixz="0.0" iyy="4" iyz="0.0" izz="4"/>
    </inertial>
  </link>
  <joint name="frame_link_joint" type="fixed">
    <parent link="base_link"/>
    <child link="frame_link"/>
    <origin rpy="0 -0 0" xyz="0 0 0"/>
  </joint>
  <gazebo reference="frame_link">
    <material>Gazebo/DarkGray</material>
  </gazebo>

<!-- Rocker right -->
  <link name="rocker_right">
    <visual>
      <geometry>
        <mesh filename="file://$(find zeus_description)/STL/rocker_right.stl"/>
      </geometry>
      <origin rpy="0 0 0" xyz="0 0 0"/>
    </visual>
    <inertial>
      <mass value="${rocker_mass}"/>
      <inertia ixx="${wheel_mass*wheel_radius*wheel_radius}" ixy="0.0" ixz="0.0" iyy="${wheel_mass*wheel_radius*wheel_radius}" iyz="0.0" izz="${wheel_mass*wheel_radius*wheel_radius}"/>
    </inertial>
  </link>
  <joint name="rocker_right_joint" type="revolute">
    <parent link="frame_link"/>
    <child link="rocker_right"/>
    <origin rpy="0 -0.2 0" xyz="-0.3 -0.3 -0.4"/>
    <limit  lower="${-deg45}" upper="${deg45}" effort="100000.0" velocity="10.0"/>
    <axis xyz="0 1 0"/>
		<joint_properties damping="0.5" friction="0.5"/>
  </joint>
  <transmission name="rocker_right_trans">
    <type>transmission_interface/SimpleTransmission</type>
    <joint name="rocker_right_joint">
      <hardwareInterface>hardware_interface/EffortJointInterface</hardwareInterface>
    </joint>
    <actuator name="rocker_right_motor">
      <hardwareInterface>hardware_interface/EffortJointInterface</hardwareInterface>
      <mechanicalReduction>1</mechanicalReduction>
    </actuator>
  </transmission>
  <gazebo reference="rocker_right">
    <material>Gazebo/Gray</material>
  </gazebo>

  <!-- Bogie right -->
  <link name="bogie_right">
    <visual>
      <geometry>
        <mesh filename="file://$(find zeus_description)/STL/bogie.stl"/>
      </geometry>
      <origin rpy="0 0 0" xyz="0 0 0"/>
      <material name="gray"/>
    </visual>
    <inertial>
      <mass value="${bogie_mass}"/>
      <inertia ixx="0.01" ixy="0.0" ixz="0.0" iyy="0.01" iyz="0.0" izz="0.01"/>
    </inertial>
  </link>
  <joint name="bogie_right_joint" type="revolute">
    <parent link="rocker_right"/>
    <child link="bogie_right"/>
    <origin rpy="0 -0.5 0" xyz="0.35 0 -0.2"/>
    <axis xyz="0 1 0"/>
    <dynamics damping="0.0" friction="10.0"/>
    <limit  lower="${-deg90}" upper="0.6" effort="100000.0" velocity="100000.0"/>
  </joint>
  <gazebo reference="bogie_right">
    <material>Gazebo/Gray</material>
  </gazebo>

  <!-- Rocker left -->
  <link name="rocker_left">
    <visual>
      <geometry>
        <mesh filename="file://$(find zeus_description)/STL/rocker_left.stl"/>
      </geometry>
      <origin rpy="0 0 0" xyz="0 0 0"/>
      <material name="gray"/>
    </visual>
    <inertial>
      <mass value="${rocker_mass}"/>
      <inertia ixx="0.01" ixy="0.0" ixz="0.0" iyy="0.01" iyz="0.0" izz="0.01"/>
    </inertial>
  </link>
  <joint name="rocker_left_joint" type="continuous">
    <parent link="frame_link"/>
    <child link="rocker_left"/>
    <origin rpy="0 -0.2 0" xyz="-0.3 0.3 -0.4"/>
    <limit  lower="${-deg45}" upper="${deg45}" effort="100000.0" velocity="10.0"/>
    <axis xyz="0 1 0"/>
		<joint_properties damping="0.5" friction="0.5"/>
  </joint>
  <transmission name="rocker_left_trans">
    <type>transmission_interface/SimpleTransmission</type>
    <joint name="rocker_left_joint">
      <hardwareInterface>hardware_interface/EffortJointInterface</hardwareInterface>
    </joint>
    <actuator name="rocker_left_motor">
      <hardwareInterface>hardware_interface/EffortJointInterface</hardwareInterface>
      <mechanicalReduction>1</mechanicalReduction>
    </actuator>
  </transmission>
  <gazebo reference="rocker_left">
    <material>Gazebo/Gray</material>
  </gazebo>

  <!-- Bogie left -->
  <link name="bogie_left">
    <visual>
      <geometry>
        <mesh filename="file://$(find zeus_description)/STL/bogie.stl"/>
      </geometry>
      <origin rpy="0 0 0" xyz="0 0 0"/>
      <material name="gray"/>
    </visual>
    <inertial>
      <mass value="${bogie_mass}"/>
      <inertia ixx="0.01" ixy="0.0" ixz="0.0" iyy="0.01" iyz="0.0" izz="0.01"/>
    </inertial>
  </link>
  <joint name="bogie_left_joint" type="revolute">
    <parent link="rocker_left"/>
    <child link="bogie_left"/>
    <origin rpy="0 -0.5 0" xyz="0.35 0 -0.2"/>
    <axis xyz="0 1 0"/>
    <dynamics damping="0.0" friction="10.0"/>
    <limit  lower="${-deg90}" upper="0.6" effort="100000.0" velocity="100000.0"/>
  </joint>
  <gazebo reference="bogie_left">
    <material>Gazebo/Gray</material>
  </gazebo>

  <!-- Wheel front right -->
  <link name="right_front_wheel">
    <visual>
      <origin rpy="0 0 0" xyz="0 0 0"/>
      <geometry>
       <mesh filename="file://$(find zeus_description)/STL/Z1-PRP-01-001.stl"/>
      </geometry>
    </visual>
    <collision>
      <geometry>
        <cylinder length="${wheel_width}" radius="${wheel_radius}"/>
      </geometry>
      <origin rpy="0 0 0" xyz="0 0 0"/>
    </collision>
    <inertial>
      <mass value="${wheel_mass}"/>
      <inertia ixx="${wheel_mass*wheel_radius*wheel_radius}" ixy="0.0" ixz="0.0" iyy="${wheel_mass*wheel_radius*wheel_radius}" iyz="0.0" izz="${wheel_mass*wheel_radius*wheel_radius}"/>
    </inertial>
  </link>
  <joint name="right_front_wheel_joint" type="continuous">
    <parent link="bogie_right"/>
    <child link="right_front_wheel"/>
   <origin rpy="${deg90} 0 0" xyz="0 -0.05 -0.45"/>
    <axis xyz="0 0 -1"/>
  </joint>
  <transmission name="right_front_wheel_trans">
    <type>transmission_interface/SimpleTransmission</type>
    <actuator name="right_front_wheel_motor">
      <mechanicalReduction>1</mechanicalReduction>
    </actuator>
    <joint name="right_front_wheel_joint">
      <hardwareInterface>hardware_interface/VelocityJointInterface</hardwareInterface> 
      <!-- <hardwareInterface>hardware_interface/EffortJointInterface</hardwareInterface>-->
    </joint>
  </transmission>
  <gazebo reference="right_front_wheel">
    <mu1 value="${wheel_mu1}"/>
    <mu2 value="${wheel_mu2}"/>
    <kp value="${wheel_kp}" />
    <kd value="${wheel_kd}" />
    <material>Gazebo/Black</material>
  </gazebo>

  <!-- Wheel middle right -->
  <link name="right_middle_wheel">
    <visual>
      <origin rpy="0 0 0" xyz="0 0 0"/>
      <geometry>
       <mesh filename="file://$(find zeus_description)/STL/Z1-PRP-01-001.stl"/>
      </geometry>
      <material name="black"/>
    </visual>
    <collision>
      <geometry>
        <cylinder length="${wheel_width}" radius="${wheel_radius}"/>
      </geometry>
      <origin rpy="0 0 0" xyz="0 0 0"/>
    </collision>
    <inertial>
      <mass value="${wheel_mass}"/>
      <inertia ixx="${wheel_mass*wheel_radius*wheel_radius}" ixy="0.0" ixz="0.0" iyy="${wheel_mass*wheel_radius*wheel_radius}" iyz="0.0" izz="${wheel_mass*wheel_radius*wheel_radius}"/>
    </inertial>
  </link>
  <joint name="right_middle_wheel_joint" type="continuous">
    <parent link="bogie_right"/>
    <child link="right_middle_wheel"/>
    <origin rpy="${deg90} 0 0" xyz="-0.45 -0.05 -0.05"/>
    <axis xyz="0 0 -1"/>
  </joint>
  <transmission name="right_middle_wheel_trans">
    <type>transmission_interface/SimpleTransmission</type>
    <actuator name="right_middle_wheel_motor">
      <mechanicalReduction>1</mechanicalReduction>
    </actuator>
    <joint name="right_middle_wheel_joint">
      <hardwareInterface>hardware_interface/VelocityJointInterface</hardwareInterface> 
      <!-- <hardwareInterface>hardware_interface/EffortJointInterface</hardwareInterface>-->
    </joint>
  </transmission>
  <gazebo reference="right_middle_wheel">
    <mu1 value="${wheel_mu1}"/>
    <mu2 value="${wheel_mu2}"/>
    <kp value="${wheel_kp}" />
    <kd value="${wheel_kd}" />
    <material>Gazebo/Black</material>
  </gazebo>

  <!-- Wheel rear right -->
  <link name="right_rear_wheel">
    <visual>
      <origin rpy="${deg90} 0 0" xyz="0 0 0"/>
      <geometry>
        <mesh filename="file://$(find zeus_description)/STL/Z1-PRP-01-001.stl"/>
      </geometry>
      <material name="black"/>
    </visual>
    <collision>
      <geometry>
        <cylinder length="${wheel_width}" radius="${wheel_radius}"/>
      </geometry>
      <origin rpy="${deg90} 0 0" xyz="0 0 0"/>
    </collision>
    <inertial>
      <mass value="${wheel_mass}"/>
      <inertia ixx="${wheel_mass*wheel_radius*wheel_radius}" ixy="0.0" ixz="0.0" iyy="${wheel_mass*wheel_radius*wheel_radius}" iyz="0.0" izz="${wheel_mass*wheel_radius*wheel_radius}"/>
    </inertial>
  </link>
  <joint name="right_rear_wheel_joint" type="continuous">
    <parent link="rocker_right"/>
    <child link="right_rear_wheel"/>
    <origin rpy="0 0 0" xyz="-0.6 -0.05 -0.35"/>
    <axis xyz="0 1 0"/>
  </joint>
  <transmission name="right_rear_wheel_trans">
    <type>transmission_interface/SimpleTransmission</type>
    <actuator name="right_rear_wheel_motor">
      <mechanicalReduction>1</mechanicalReduction>
    </actuator>
    <joint name="right_rear_wheel_joint">
      <hardwareInterface>hardware_interface/VelocityJointInterface</hardwareInterface> 
      <!-- <hardwareInterface>hardware_interface/EffortJointInterface</hardwareInterface>-->
    </joint>
  </transmission>
  <gazebo reference="right_rear_wheel">
    <mu1 value="${wheel_mu1}"/>
    <mu2 value="${wheel_mu2}"/>
    <kp value="${wheel_kp}" />
    <kd value="${wheel_kd}" />
    <material>Gazebo/Black</material>
  </gazebo>

  <!-- Wheel front left -->
  <link name="left_front_wheel">
    <visual>
      <origin rpy="0 0 0" xyz="0 0 0"/>
      <geometry>
       <mesh filename="file://$(find zeus_description)/STL/Z1-PRP-01-001.stl"/>
      </geometry>
      <material name="black"/>
    </visual>
    <collision>
      <geometry>
        <cylinder length="${wheel_width}" radius="${wheel_radius}"/>
      </geometry>
      <origin rpy="0 0 0" xyz="0 0 0"/>
    </collision>
    <inertial>
      <mass value="${wheel_mass}"/>
      <inertia ixx="${wheel_mass*wheel_radius*wheel_radius}" ixy="0.0" ixz="0.0" iyy="${wheel_mass*wheel_radius*wheel_radius}" iyz="0.0" izz="${wheel_mass*wheel_radius*wheel_radius}"/>
    </inertial>
  </link>
  <joint name="left_front_wheel_joint" type="continuous">
    <parent link="bogie_left"/>
    <child link="left_front_wheel"/>
   <origin rpy="${deg90} 0 0" xyz="0 0.05 -0.45"/>
    <axis xyz="0 0 -1"/>
  </joint>
  <transmission name="left_front_wheel_trans">
    <type>transmission_interface/SimpleTransmission</type>
    <actuator name="left_front_wheel_motor">
      <mechanicalReduction>1</mechanicalReduction>
    </actuator>
    <joint name="left_front_wheel_joint">
      <hardwareInterface>hardware_interface/VelocityJointInterface</hardwareInterface> 
      <!-- <hardwareInterface>hardware_interface/EffortJointInterface</hardwareInterface>-->
    </joint>
  </transmission>
  <gazebo reference="left_front_wheel">
    <mu1 value="${wheel_mu1}"/>
    <mu2 value="${wheel_mu2}"/>
    <kp value="${wheel_kp}" />
    <kd value="${wheel_kd}" />
    <material>Gazebo/Black</material>
  </gazebo>

  <!-- Wheel middle left -->
  <link name="left_middle_wheel">
    <visual>
      <origin rpy="0 0 0" xyz="0 0 0"/>
      <geometry>
       <mesh filename="file://$(find zeus_description)/STL/Z1-PRP-01-001.stl"/>
      </geometry>
      <material name="black"/>
    </visual>
    <collision>
      <geometry>
        <cylinder length="${wheel_width}" radius="${wheel_radius}"/>
      </geometry>
      <origin rpy="0 0 0" xyz="0 0 0"/>
    </collision>
    <inertial>
      <mass value="${wheel_mass}"/>
      <inertia ixx="${wheel_mass*wheel_radius*wheel_radius}" ixy="0.0" ixz="0.0" iyy="${wheel_mass*wheel_radius*wheel_radius}" iyz="0.0" izz="${wheel_mass*wheel_radius*wheel_radius}"/>
    </inertial>
  </link>
  <joint name="left_middle_wheel_joint" type="continuous">
    <parent link="bogie_left"/>
    <child link="left_middle_wheel"/>
    <origin rpy="${deg90} 0 0" xyz="-0.45 0.05 -0.05"/>
    <axis xyz="0 0 -1"/>
  </joint>
  <transmission name="left_middle_wheel_trans">
    <type>transmission_interface/SimpleTransmission</type>
    <actuator name="left_middle_wheel_motor">
      <mechanicalReduction>1</mechanicalReduction>
    </actuator>
    <joint name="left_middle_wheel_joint">
      <hardwareInterface>hardware_interface/VelocityJointInterface</hardwareInterface> 
      <!-- <hardwareInterface>hardware_interface/EffortJointInterface</hardwareInterface>-->
    </joint>
  </transmission>
  <gazebo reference="left_middle_wheel">
    <mu1 value="${wheel_mu1}"/>
    <mu2 value="${wheel_mu2}"/>
    <kp value="${wheel_kp}" />
    <kd value="${wheel_kd}" />
    <material>Gazebo/Black</material>
  </gazebo>

  <!-- Wheel rear left -->
  <link name="left_rear_wheel">
    <visual>
      <origin rpy="${deg90} 0 0" xyz="0 0 0"/>
      <geometry>
        <mesh filename="file://$(find zeus_description)/STL/Z1-PRP-01-001.stl"/>
      </geometry>
      <material name="black"/>
    </visual>
    <collision>
      <geometry>
       <cylinder length="${wheel_width}" radius="${wheel_radius}"/>
      </geometry>
      <origin rpy="${deg90} 0 0" xyz="0 0 0"/>
    </collision>
    <inertial>
      <mass value="${wheel_mass}"/>
      <inertia ixx="${wheel_mass*wheel_radius*wheel_radius}" ixy="0.0" ixz="0.0" iyy="${wheel_mass*wheel_radius*wheel_radius}" iyz="0.0" izz="${wheel_mass*wheel_radius*wheel_radius}"/>
    </inertial>
  </link>
  <joint name="left_rear_wheel_joint" type="continuous">
    <parent link="rocker_left"/>
    <child link="left_rear_wheel"/>
    <origin rpy="0 0 0" xyz="-0.6 0.05 -0.35"/>
    <axis xyz="0 1 0"/>
  </joint>
  <transmission name="left_rear_wheel_trans">
    <type>transmission_interface/SimpleTransmission</type>
    <actuator name="left_rear_wheel_motor">
      <mechanicalReduction>1</mechanicalReduction>
    </actuator>
    <joint name="left_rear_wheel_joint">
      <hardwareInterface>hardware_interface/VelocityJointInterface</hardwareInterface> 
      <!-- <hardwareInterface>hardware_interface/EffortJointInterface</hardwareInterface>-->
    </joint>
  </transmission>
  <gazebo reference="left_rear_wheel">
    <mu1 value="${wheel_mu1}"/>
    <mu2 value="${wheel_mu2}"/>
    <kp value="${wheel_kp}" />
    <kd value="${wheel_kd}" />
    <material>Gazebo/Black</material>
  </gazebo>

  <!-- IMU link -->
  <link name="imu_link"/>

  <joint name="imu_joint" type="fixed">
    <origin xyz="0 0 0" rpy="0 0 0" />
    <parent link="base_link" />
    <child link="imu_link" />
  </joint>
  <gazebo reference="imu_link">
  </gazebo>

   <!-- Camera -->
  <xacro:camera_sensor name="camera1" parent="base_link" hfov="1.3962634" image_width="800" image_height="600"  >
    <origin xyz="0.1 0 0" rpy="0 0 0" />
  </xacro:camera_sensor>

  <!-- Intel RealSense d435 -->
  <xacro:realsense_d435_sensor name="d435" parent="base_link" >
    <origin xyz="0 0 0.5" rpy="0 0 0" />
  </xacro:realsense_d435_sensor>

  <!-- Controllers -->
  <gazebo>
    <plugin name="gazebo_ros_control" filename="libgazebo_ros_control.so">
      <robotNamespace>zeus</robotNamespace>
    </plugin>
  </gazebo>

  <!-- Gazebo plugins -->
  <gazebo>
    <plugin name="imu_controller" filename="libhector_gazebo_ros_imu.so">
      <robotNamespace>$(arg robot_namespace)</robotNamespace>
      <updateRate>50</updateRate>
      <bodyName>base_link</bodyName>
      <topicName>/imu/data</topicName>
      <accelDrift>0.005 0.005 0.005</accelDrift>
      <accelGaussianNoise>0.005 0.005 0.005</accelGaussianNoise>
      <rateDrift>0.005 0.005 0.005 </rateDrift>
      <rateGaussianNoise>0.005 0.005 0.005 </rateGaussianNoise>
      <headingDrift>0.005</headingDrift>
      <headingGaussianNoise>0.005</headingGaussianNoise>
    </plugin>
  </gazebo>

  <gazebo>
    <plugin name="gps_controller" filename="libhector_gazebo_ros_gps.so">
      <robotNamespace>$(arg robot_namespace)</robotNamespace>
      <updateRate>1</updateRate>
      <bodyName>base_link</bodyName>
      <frameId>base_link</frameId>
      <topicName>/fix</topicName>
      <velocityTopicName>navsat/vel</velocityTopicName>
      <referenceLatitude>45.378395</referenceLatitude>
      <referenceLongitude>-71.926644</referenceLongitude>
      <referenceHeading>90</referenceHeading>
      <referenceAltitude>0</referenceAltitude>
      <drift>0.05 0.05 0.05</drift>
      <gaussianNoise>1 1 1</gaussianNoise>
    </plugin>
  </gazebo>

</robot>
